[2025-02-21T07:39:15.948+0000] {taskinstance.py:1159} INFO - Dependencies all met for dep_context=non-requeueable deps ti=<TaskInstance: sync_postgres_to_postgres_transaction_and_amount.process_kafka_transaction_messages manual__2025-02-21T07:39:15.203967+00:00 [queued]>
[2025-02-21T07:39:15.959+0000] {taskinstance.py:1159} INFO - Dependencies all met for dep_context=requeueable deps ti=<TaskInstance: sync_postgres_to_postgres_transaction_and_amount.process_kafka_transaction_messages manual__2025-02-21T07:39:15.203967+00:00 [queued]>
[2025-02-21T07:39:15.959+0000] {taskinstance.py:1361} INFO - Starting attempt 1 of 1
[2025-02-21T07:39:15.974+0000] {taskinstance.py:1382} INFO - Executing <Task(PythonOperator): process_kafka_transaction_messages> on 2025-02-21 07:39:15.203967+00:00
[2025-02-21T07:39:15.984+0000] {standard_task_runner.py:57} INFO - Started process 368 to run task
[2025-02-21T07:39:15.988+0000] {standard_task_runner.py:84} INFO - Running: ['***', 'tasks', 'run', 'sync_postgres_to_postgres_transaction_and_amount', 'process_kafka_transaction_messages', 'manual__2025-02-21T07:39:15.203967+00:00', '--job-id', '10', '--raw', '--subdir', 'DAGS_FOLDER/sync_postgres_dag.py', '--cfg-path', '/tmp/tmp8ivpb5vd']
[2025-02-21T07:39:15.989+0000] {standard_task_runner.py:85} INFO - Job 10: Subtask process_kafka_transaction_messages
[2025-02-21T07:39:16.049+0000] {task_command.py:416} INFO - Running <TaskInstance: sync_postgres_to_postgres_transaction_and_amount.process_kafka_transaction_messages manual__2025-02-21T07:39:15.203967+00:00 [running]> on host e5982255e08e
[2025-02-21T07:39:16.148+0000] {taskinstance.py:1662} INFO - Exporting env vars: AIRFLOW_CTX_DAG_OWNER='***' AIRFLOW_CTX_DAG_ID='sync_postgres_to_postgres_transaction_and_amount' AIRFLOW_CTX_TASK_ID='process_kafka_transaction_messages' AIRFLOW_CTX_EXECUTION_DATE='2025-02-21T07:39:15.203967+00:00' AIRFLOW_CTX_TRY_NUMBER='1' AIRFLOW_CTX_DAG_RUN_ID='manual__2025-02-21T07:39:15.203967+00:00'
[2025-02-21T07:39:16.150+0000] {sync_postgres_dag.py:27} INFO - Starting Kafka consumer for transaction messages...
[2025-02-21T07:39:16.152+0000] {conn.py:380} INFO - <BrokerConnection node_id=bootstrap-0 host=172.17.0.1:9092 <connecting> [IPv4 ('172.17.0.1', 9092)]>: connecting to 172.17.0.1:9092 [('172.17.0.1', 9092) IPv4]
[2025-02-21T07:39:16.153+0000] {conn.py:1206} INFO - Probing node bootstrap-0 broker version
[2025-02-21T07:39:16.153+0000] {conn.py:410} INFO - <BrokerConnection node_id=bootstrap-0 host=172.17.0.1:9092 <connecting> [IPv4 ('172.17.0.1', 9092)]>: Connection complete.
[2025-02-21T07:39:16.260+0000] {conn.py:1268} INFO - Broker version identified as 2.6.0
[2025-02-21T07:39:16.261+0000] {conn.py:1269} INFO - Set configuration api_version=(2, 6, 0) to skip auto check_version requests on startup
[2025-02-21T07:39:16.262+0000] {subscription_state.py:171} INFO - Updating subscribed topics to: ('from_mysql_transaction',)
[2025-02-21T07:39:16.263+0000] {sync_postgres_dag.py:38} INFO - Connected to Kafka broker at 172.17.0.1:9092
[2025-02-21T07:39:16.263+0000] {taskinstance.py:1937} ERROR - Task failed with exception
Traceback (most recent call last):
  File "/home/airflow/.local/lib/python3.8/site-packages/airflow/operators/python.py", line 192, in execute
    return_value = self.execute_callable()
  File "/home/airflow/.local/lib/python3.8/site-packages/airflow/operators/python.py", line 209, in execute_callable
    return self.python_callable(*self.op_args, **self.op_kwargs)
  File "/opt/airflow/dags/sync_postgres_dag.py", line 40, in process_kafka_transaction_messages
    conn = psycopg2.connect(**db_config)
  File "/home/airflow/.local/lib/python3.8/site-packages/psycopg2/__init__.py", line 122, in connect
    conn = _connect(dsn, connection_factory=connection_factory, **kwasync)
psycopg2.OperationalError: connection to server at "localhost" (::1), port 5433 failed: Connection refused
	Is the server running on that host and accepting TCP/IP connections?
connection to server at "localhost" (127.0.0.1), port 5433 failed: Connection refused
	Is the server running on that host and accepting TCP/IP connections?

[2025-02-21T07:39:16.281+0000] {taskinstance.py:1400} INFO - Marking task as FAILED. dag_id=sync_postgres_to_postgres_transaction_and_amount, task_id=process_kafka_transaction_messages, execution_date=20250221T073915, start_date=20250221T073915, end_date=20250221T073916
[2025-02-21T07:39:16.299+0000] {standard_task_runner.py:104} ERROR - Failed to execute job 10 for task process_kafka_transaction_messages (connection to server at "localhost" (::1), port 5433 failed: Connection refused
	Is the server running on that host and accepting TCP/IP connections?
connection to server at "localhost" (127.0.0.1), port 5433 failed: Connection refused
	Is the server running on that host and accepting TCP/IP connections?
; 368)
[2025-02-21T07:39:16.320+0000] {local_task_job_runner.py:228} INFO - Task exited with return code 1
[2025-02-21T07:39:16.349+0000] {taskinstance.py:2778} INFO - 0 downstream tasks scheduled from follow-on schedule check
